[2023-08-07 07:27:28,664] {taskinstance.py:1159} INFO - Dependencies all met for <TaskInstance: dados_climaticos.Requisita_tempo scheduled__2023-07-31T00:00:00+00:00 [queued]>
[2023-08-07 07:27:28,669] {taskinstance.py:1159} INFO - Dependencies all met for <TaskInstance: dados_climaticos.Requisita_tempo scheduled__2023-07-31T00:00:00+00:00 [queued]>
[2023-08-07 07:27:28,669] {taskinstance.py:1356} INFO - 
--------------------------------------------------------------------------------
[2023-08-07 07:27:28,669] {taskinstance.py:1357} INFO - Starting attempt 1 of 1
[2023-08-07 07:27:28,669] {taskinstance.py:1358} INFO - 
--------------------------------------------------------------------------------
[2023-08-07 07:27:28,681] {taskinstance.py:1377} INFO - Executing <Task(PythonOperator): Requisita_tempo> on 2023-07-31 00:00:00+00:00
[2023-08-07 07:27:28,685] {standard_task_runner.py:52} INFO - Started process 7319 to run task
[2023-08-07 07:27:28,687] {standard_task_runner.py:79} INFO - Running: ['airflow', 'tasks', 'run', 'dados_climaticos', 'Requisita_tempo', 'scheduled__2023-07-31T00:00:00+00:00', '--job-id', '23', '--raw', '--subdir', 'DAGS_FOLDER/dados_climaticos.py', '--cfg-path', '/tmp/tmp105f9f30', '--error-file', '/tmp/tmpl0p2_qos']
[2023-08-07 07:27:28,688] {standard_task_runner.py:80} INFO - Job 23: Subtask Requisita_tempo
[2023-08-07 07:27:28,718] {task_command.py:370} INFO - Running <TaskInstance: dados_climaticos.Requisita_tempo scheduled__2023-07-31T00:00:00+00:00 [running]> on host Daniel.
[2023-08-07 07:27:28,756] {taskinstance.py:1569} INFO - Exporting the following env vars:
AIRFLOW_CTX_DAG_OWNER=airflow
AIRFLOW_CTX_DAG_ID=dados_climaticos
AIRFLOW_CTX_TASK_ID=Requisita_tempo
AIRFLOW_CTX_EXECUTION_DATE=2023-07-31T00:00:00+00:00
AIRFLOW_CTX_TRY_NUMBER=1
AIRFLOW_CTX_DAG_RUN_ID=scheduled__2023-07-31T00:00:00+00:00
[2023-08-07 07:27:28,757] {taskinstance.py:1889} ERROR - Task failed with exception
Traceback (most recent call last):
  File "/home/daniel/Documents/airflow_dados_tempo/venv/lib/python3.9/site-packages/airflow/operators/python.py", line 171, in execute
    return_value = self.execute_callable()
  File "/home/daniel/Documents/airflow_dados_tempo/venv/lib/python3.9/site-packages/airflow/operators/python.py", line 189, in execute_callable
    return self.python_callable(*self.op_args, **self.op_kwargs)
  File "/home/daniel/Documents/airflow_dados_tempo/dags/dados_climaticos.py", line 10, in clima_tempo
    tempo = CimlaTempo()
TypeError: __init__() missing 1 required positional argument: 'data'
[2023-08-07 07:27:28,759] {taskinstance.py:1395} INFO - Marking task as FAILED. dag_id=dados_climaticos, task_id=Requisita_tempo, execution_date=20230731T000000, start_date=20230807T102728, end_date=20230807T102728
[2023-08-07 07:27:28,769] {standard_task_runner.py:92} ERROR - Failed to execute job 23 for task Requisita_tempo (__init__() missing 1 required positional argument: 'data'; 7319)
[2023-08-07 07:27:28,780] {local_task_job.py:156} INFO - Task exited with return code 1
[2023-08-07 07:27:28,791] {local_task_job.py:273} INFO - 0 downstream tasks scheduled from follow-on schedule check
[2023-08-07 07:31:20,530] {taskinstance.py:1159} INFO - Dependencies all met for <TaskInstance: dados_climaticos.Requisita_tempo scheduled__2023-07-31T00:00:00+00:00 [queued]>
[2023-08-07 07:31:20,535] {taskinstance.py:1159} INFO - Dependencies all met for <TaskInstance: dados_climaticos.Requisita_tempo scheduled__2023-07-31T00:00:00+00:00 [queued]>
[2023-08-07 07:31:20,535] {taskinstance.py:1356} INFO - 
--------------------------------------------------------------------------------
[2023-08-07 07:31:20,535] {taskinstance.py:1357} INFO - Starting attempt 1 of 1
[2023-08-07 07:31:20,535] {taskinstance.py:1358} INFO - 
--------------------------------------------------------------------------------
[2023-08-07 07:31:20,547] {taskinstance.py:1377} INFO - Executing <Task(PythonOperator): Requisita_tempo> on 2023-07-31 00:00:00+00:00
[2023-08-07 07:31:20,549] {standard_task_runner.py:52} INFO - Started process 7746 to run task
[2023-08-07 07:31:20,551] {standard_task_runner.py:79} INFO - Running: ['airflow', 'tasks', 'run', 'dados_climaticos', 'Requisita_tempo', 'scheduled__2023-07-31T00:00:00+00:00', '--job-id', '23', '--raw', '--subdir', 'DAGS_FOLDER/dados_climaticos.py', '--cfg-path', '/tmp/tmpgz91m8si', '--error-file', '/tmp/tmp8yme3i3w']
[2023-08-07 07:31:20,552] {standard_task_runner.py:80} INFO - Job 23: Subtask Requisita_tempo
[2023-08-07 07:31:20,581] {task_command.py:370} INFO - Running <TaskInstance: dados_climaticos.Requisita_tempo scheduled__2023-07-31T00:00:00+00:00 [running]> on host Daniel.
[2023-08-07 07:31:20,620] {taskinstance.py:1569} INFO - Exporting the following env vars:
AIRFLOW_CTX_DAG_OWNER=airflow
AIRFLOW_CTX_DAG_ID=dados_climaticos
AIRFLOW_CTX_TASK_ID=Requisita_tempo
AIRFLOW_CTX_EXECUTION_DATE=2023-07-31T00:00:00+00:00
AIRFLOW_CTX_TRY_NUMBER=1
AIRFLOW_CTX_DAG_RUN_ID=scheduled__2023-07-31T00:00:00+00:00
[2023-08-07 07:31:20,621] {taskinstance.py:1889} ERROR - Task failed with exception
Traceback (most recent call last):
  File "/home/daniel/Documents/airflow_dados_tempo/venv/lib/python3.9/site-packages/airflow/operators/python.py", line 171, in execute
    return_value = self.execute_callable()
  File "/home/daniel/Documents/airflow_dados_tempo/venv/lib/python3.9/site-packages/airflow/operators/python.py", line 189, in execute_callable
    return self.python_callable(*self.op_args, **self.op_kwargs)
  File "/home/daniel/Documents/airflow_dados_tempo/dags/dados_climaticos.py", line 10, in clima_tempo
    tempo = ClimaTempo()
TypeError: __init__() missing 1 required positional argument: 'data'
[2023-08-07 07:31:20,623] {taskinstance.py:1395} INFO - Marking task as FAILED. dag_id=dados_climaticos, task_id=Requisita_tempo, execution_date=20230731T000000, start_date=20230807T103120, end_date=20230807T103120
[2023-08-07 07:31:20,633] {standard_task_runner.py:92} ERROR - Failed to execute job 23 for task Requisita_tempo (__init__() missing 1 required positional argument: 'data'; 7746)
[2023-08-07 07:31:20,644] {local_task_job.py:156} INFO - Task exited with return code 1
[2023-08-07 07:31:20,655] {local_task_job.py:273} INFO - 0 downstream tasks scheduled from follow-on schedule check
[2023-08-07 07:32:52,516] {taskinstance.py:1159} INFO - Dependencies all met for <TaskInstance: dados_climaticos.Requisita_tempo scheduled__2023-07-31T00:00:00+00:00 [queued]>
[2023-08-07 07:32:52,521] {taskinstance.py:1159} INFO - Dependencies all met for <TaskInstance: dados_climaticos.Requisita_tempo scheduled__2023-07-31T00:00:00+00:00 [queued]>
[2023-08-07 07:32:52,521] {taskinstance.py:1356} INFO - 
--------------------------------------------------------------------------------
[2023-08-07 07:32:52,521] {taskinstance.py:1357} INFO - Starting attempt 1 of 1
[2023-08-07 07:32:52,521] {taskinstance.py:1358} INFO - 
--------------------------------------------------------------------------------
[2023-08-07 07:32:52,533] {taskinstance.py:1377} INFO - Executing <Task(PythonOperator): Requisita_tempo> on 2023-07-31 00:00:00+00:00
[2023-08-07 07:32:52,535] {standard_task_runner.py:52} INFO - Started process 7914 to run task
[2023-08-07 07:32:52,537] {standard_task_runner.py:79} INFO - Running: ['airflow', 'tasks', 'run', 'dados_climaticos', 'Requisita_tempo', 'scheduled__2023-07-31T00:00:00+00:00', '--job-id', '23', '--raw', '--subdir', 'DAGS_FOLDER/dados_climaticos.py', '--cfg-path', '/tmp/tmp3028ll3d', '--error-file', '/tmp/tmpy8a_u_f1']
[2023-08-07 07:32:52,538] {standard_task_runner.py:80} INFO - Job 23: Subtask Requisita_tempo
[2023-08-07 07:32:52,569] {task_command.py:370} INFO - Running <TaskInstance: dados_climaticos.Requisita_tempo scheduled__2023-07-31T00:00:00+00:00 [running]> on host Daniel.
[2023-08-07 07:32:52,609] {taskinstance.py:1569} INFO - Exporting the following env vars:
AIRFLOW_CTX_DAG_OWNER=airflow
AIRFLOW_CTX_DAG_ID=dados_climaticos
AIRFLOW_CTX_TASK_ID=Requisita_tempo
AIRFLOW_CTX_EXECUTION_DATE=2023-07-31T00:00:00+00:00
AIRFLOW_CTX_TRY_NUMBER=1
AIRFLOW_CTX_DAG_RUN_ID=scheduled__2023-07-31T00:00:00+00:00
[2023-08-07 07:32:52,609] {taskinstance.py:1889} ERROR - Task failed with exception
Traceback (most recent call last):
  File "/home/daniel/Documents/airflow_dados_tempo/venv/lib/python3.9/site-packages/airflow/operators/python.py", line 171, in execute
    return_value = self.execute_callable()
  File "/home/daniel/Documents/airflow_dados_tempo/venv/lib/python3.9/site-packages/airflow/operators/python.py", line 189, in execute_callable
    return self.python_callable(*self.op_args, **self.op_kwargs)
  File "/home/daniel/Documents/airflow_dados_tempo/dags/dados_climaticos.py", line 10, in clima_tempo
    tempo = ClimaTempo()
TypeError: __init__() missing 1 required positional argument: 'data'
[2023-08-07 07:32:52,612] {taskinstance.py:1395} INFO - Marking task as FAILED. dag_id=dados_climaticos, task_id=Requisita_tempo, execution_date=20230731T000000, start_date=20230807T103252, end_date=20230807T103252
[2023-08-07 07:32:52,622] {standard_task_runner.py:92} ERROR - Failed to execute job 23 for task Requisita_tempo (__init__() missing 1 required positional argument: 'data'; 7914)
[2023-08-07 07:32:52,630] {local_task_job.py:156} INFO - Task exited with return code 1
[2023-08-07 07:32:52,641] {local_task_job.py:273} INFO - 0 downstream tasks scheduled from follow-on schedule check
[2023-08-07 07:34:03,222] {taskinstance.py:1159} INFO - Dependencies all met for <TaskInstance: dados_climaticos.Requisita_tempo scheduled__2023-07-31T00:00:00+00:00 [queued]>
[2023-08-07 07:34:03,228] {taskinstance.py:1159} INFO - Dependencies all met for <TaskInstance: dados_climaticos.Requisita_tempo scheduled__2023-07-31T00:00:00+00:00 [queued]>
[2023-08-07 07:34:03,229] {taskinstance.py:1356} INFO - 
--------------------------------------------------------------------------------
[2023-08-07 07:34:03,229] {taskinstance.py:1357} INFO - Starting attempt 1 of 1
[2023-08-07 07:34:03,229] {taskinstance.py:1358} INFO - 
--------------------------------------------------------------------------------
[2023-08-07 07:34:03,240] {taskinstance.py:1377} INFO - Executing <Task(PythonOperator): Requisita_tempo> on 2023-07-31 00:00:00+00:00
[2023-08-07 07:34:03,242] {standard_task_runner.py:52} INFO - Started process 8043 to run task
[2023-08-07 07:34:03,245] {standard_task_runner.py:79} INFO - Running: ['airflow', 'tasks', 'run', 'dados_climaticos', 'Requisita_tempo', 'scheduled__2023-07-31T00:00:00+00:00', '--job-id', '23', '--raw', '--subdir', 'DAGS_FOLDER/dados_climaticos.py', '--cfg-path', '/tmp/tmp826793ou', '--error-file', '/tmp/tmpjhb1uc0x']
[2023-08-07 07:34:03,245] {standard_task_runner.py:80} INFO - Job 23: Subtask Requisita_tempo
[2023-08-07 07:34:03,274] {task_command.py:370} INFO - Running <TaskInstance: dados_climaticos.Requisita_tempo scheduled__2023-07-31T00:00:00+00:00 [running]> on host Daniel.
[2023-08-07 07:34:03,314] {taskinstance.py:1569} INFO - Exporting the following env vars:
AIRFLOW_CTX_DAG_OWNER=airflow
AIRFLOW_CTX_DAG_ID=dados_climaticos
AIRFLOW_CTX_TASK_ID=Requisita_tempo
AIRFLOW_CTX_EXECUTION_DATE=2023-07-31T00:00:00+00:00
AIRFLOW_CTX_TRY_NUMBER=1
AIRFLOW_CTX_DAG_RUN_ID=scheduled__2023-07-31T00:00:00+00:00
[2023-08-07 07:34:03,315] {taskinstance.py:1889} ERROR - Task failed with exception
Traceback (most recent call last):
  File "/home/daniel/Documents/airflow_dados_tempo/venv/lib/python3.9/site-packages/airflow/operators/python.py", line 171, in execute
    return_value = self.execute_callable()
  File "/home/daniel/Documents/airflow_dados_tempo/venv/lib/python3.9/site-packages/airflow/operators/python.py", line 189, in execute_callable
    return self.python_callable(*self.op_args, **self.op_kwargs)
  File "/home/daniel/Documents/airflow_dados_tempo/dags/dados_climaticos.py", line 12, in clima_tempo
    tempo.tempo()
  File "/home/daniel/Documents/airflow_dados_tempo//dags/extrai_infos_clima.py", line 16, in tempo
    f'{city}/{self.data}/{self.data + timedelta(days=7)}?unitGroup=metric&include=days&key={key}&contentType=csv')
TypeError: can only concatenate str (not "datetime.timedelta") to str
[2023-08-07 07:34:03,317] {taskinstance.py:1395} INFO - Marking task as FAILED. dag_id=dados_climaticos, task_id=Requisita_tempo, execution_date=20230731T000000, start_date=20230807T103403, end_date=20230807T103403
[2023-08-07 07:34:03,327] {standard_task_runner.py:92} ERROR - Failed to execute job 23 for task Requisita_tempo (can only concatenate str (not "datetime.timedelta") to str; 8043)
[2023-08-07 07:34:03,337] {local_task_job.py:156} INFO - Task exited with return code 1
[2023-08-07 07:34:03,349] {local_task_job.py:273} INFO - 0 downstream tasks scheduled from follow-on schedule check
[2023-08-07 07:37:25,291] {taskinstance.py:1159} INFO - Dependencies all met for <TaskInstance: dados_climaticos.Requisita_tempo scheduled__2023-07-31T00:00:00+00:00 [queued]>
[2023-08-07 07:37:25,297] {taskinstance.py:1159} INFO - Dependencies all met for <TaskInstance: dados_climaticos.Requisita_tempo scheduled__2023-07-31T00:00:00+00:00 [queued]>
[2023-08-07 07:37:25,297] {taskinstance.py:1356} INFO - 
--------------------------------------------------------------------------------
[2023-08-07 07:37:25,297] {taskinstance.py:1357} INFO - Starting attempt 1 of 1
[2023-08-07 07:37:25,297] {taskinstance.py:1358} INFO - 
--------------------------------------------------------------------------------
[2023-08-07 07:37:25,309] {taskinstance.py:1377} INFO - Executing <Task(PythonOperator): Requisita_tempo> on 2023-07-31 00:00:00+00:00
[2023-08-07 07:37:25,312] {standard_task_runner.py:52} INFO - Started process 8354 to run task
[2023-08-07 07:37:25,314] {standard_task_runner.py:79} INFO - Running: ['airflow', 'tasks', 'run', 'dados_climaticos', 'Requisita_tempo', 'scheduled__2023-07-31T00:00:00+00:00', '--job-id', '23', '--raw', '--subdir', 'DAGS_FOLDER/dados_climaticos.py', '--cfg-path', '/tmp/tmptvbicp4i', '--error-file', '/tmp/tmply3clcos']
[2023-08-07 07:37:25,315] {standard_task_runner.py:80} INFO - Job 23: Subtask Requisita_tempo
[2023-08-07 07:37:25,347] {task_command.py:370} INFO - Running <TaskInstance: dados_climaticos.Requisita_tempo scheduled__2023-07-31T00:00:00+00:00 [running]> on host Daniel.
[2023-08-07 07:37:25,386] {taskinstance.py:1569} INFO - Exporting the following env vars:
AIRFLOW_CTX_DAG_OWNER=airflow
AIRFLOW_CTX_DAG_ID=dados_climaticos
AIRFLOW_CTX_TASK_ID=Requisita_tempo
AIRFLOW_CTX_EXECUTION_DATE=2023-07-31T00:00:00+00:00
AIRFLOW_CTX_TRY_NUMBER=1
AIRFLOW_CTX_DAG_RUN_ID=scheduled__2023-07-31T00:00:00+00:00
[2023-08-07 07:37:25,386] {taskinstance.py:1889} ERROR - Task failed with exception
Traceback (most recent call last):
  File "/home/daniel/Documents/airflow_dados_tempo/venv/lib/python3.9/site-packages/airflow/operators/python.py", line 171, in execute
    return_value = self.execute_callable()
  File "/home/daniel/Documents/airflow_dados_tempo/venv/lib/python3.9/site-packages/airflow/operators/python.py", line 189, in execute_callable
    return self.python_callable(*self.op_args, **self.op_kwargs)
  File "/home/daniel/Documents/airflow_dados_tempo/dags/dados_climaticos.py", line 12, in clima_tempo
    tempo.tempo()
  File "/home/daniel/Documents/airflow_dados_tempo//dags/extrai_infos_clima.py", line 16, in tempo
    f'{city}/{self.data.strftime("%Y-%m-%d")}?unitGroup=metric&include=days&key={key}&contentType=csv')
AttributeError: 'str' object has no attribute 'strftime'
[2023-08-07 07:37:25,389] {taskinstance.py:1395} INFO - Marking task as FAILED. dag_id=dados_climaticos, task_id=Requisita_tempo, execution_date=20230731T000000, start_date=20230807T103725, end_date=20230807T103725
[2023-08-07 07:37:25,398] {standard_task_runner.py:92} ERROR - Failed to execute job 23 for task Requisita_tempo ('str' object has no attribute 'strftime'; 8354)
[2023-08-07 07:37:25,407] {local_task_job.py:156} INFO - Task exited with return code 1
[2023-08-07 07:37:25,418] {local_task_job.py:273} INFO - 0 downstream tasks scheduled from follow-on schedule check
